<?xml version="1.0"?>
<!-- Copyright (c) 2016 The UUV Simulator Authors.
     All rights reserved.

     Licensed under the Apache License, Version 2.0 (the "License");
     you may not use this file except in compliance with the License.
     You may obtain a copy of the License at

       http://www.apache.org/licenses/LICENSE-2.0

     Unless required by applicable law or agreed to in writing, software
     distributed under the License is distributed on an "AS IS" BASIS,
     WITHOUT WARRANTIES OR CONDITIONS OF ANY KIND, either express or implied.
     See the License for the specific language governing permissions and
     limitations under the License.
-->
<robot xmlns:xacro="http://www.ros.org/wiki/xacro">

    <!-- Ground base -->

    <link name="${namespace}/end_effector">
        <xacro:link_box_inertial mass="${total_mass * gripper_base_volume / total_volume}"
                    width="${gripper_base_width}"
                    length="${gripper_base_length}"
                    height="${gripper_base_height}">
        <origin xyz="${gripper_base_com}" rpy="0 0 0"/>
        </xacro:link_box_inertial>

        <visual>
            <origin xyz="0 0 0" rpy="0 0 0"/>
            <geometry>
                <mesh filename="file://$(find oberon7_description)/meshes/parallel_gripper/visual/BaseGripper.dae"/>
            </geometry>
        </visual>

        <collision>
            <origin xyz="${gripper_base_com}" rpy="0 0 0"/>
            <geometry>
                <box size="${gripper_base_length} ${gripper_base_width} ${gripper_base_height}"/>
            </geometry>
        </collision>
    </link>

    <joint name="${namespace}/wrist" type="revolute">
      <parent link="${namespace}/wrist_link"/>
      <child link="${namespace}/end_effector"/>
       <origin xyz="0.19304 0 0" rpy="${-PI*0.5} 0 0"/>
      <axis xyz="1 0 0"/>
      <dynamics damping="10" friction="5"/>
      <limit effort="10" lower="${-2*PI}" upper="${2*PI}" velocity="${gripper_velocity}"/>
    </joint>

    <xacro:simple_transmission joint="${namespace}/wrist" />

    <!-- Finger left  -->

    <link name="${namespace}/finger_left">
        <xacro:link_box_inertial mass="${total_mass * finger_volume / total_volume}"
                    width="${finger_width}"
                    length="${finger_length}"
                    height="${finger_height}">
        <origin xyz="${finger_com}" rpy="0 0 0"/>
        </xacro:link_box_inertial>

        <visual>
            <origin xyz="0 0 0" rpy="0 0 0"/>
            <geometry>
                <mesh filename="file://$(find oberon7_description)/meshes/parallel_gripper/visual/Finger.dae"/>
            </geometry>
        </visual>

        <collision>
            <origin xyz="0 0 0" rpy="0 0 0"/>
            <geometry>
                <mesh filename="file://$(find oberon7_description)/meshes/parallel_gripper/visual/Finger.dae"/>
            </geometry>
        </collision>
    </link>

    <joint name="${namespace}/finger_left_joint" type="revolute">
        <parent link="${namespace}/end_effector"/>
        <child link="${namespace}/finger_left"/>
        <origin xyz="0.0444267 0.0391376 0" rpy="0 0 0"/>
        <axis xyz="0 0 1"/>
        <dynamics damping="5" friction="10"/>
        <limit effort="${gripper_effort}" lower="0" upper="${PI*0.3333}" velocity="${gripper_velocity}"/>
    </joint>

    <xacro:simple_transmission joint="${namespace}/finger_left_joint" />

    <!-- Finger tip left  -->

    <link name="${namespace}/finger_tip_left">
        <xacro:link_box_inertial mass="${total_mass * finger_tip_volume / total_volume}"
                    width="${finger_tip_width}"
                    length="${finger_tip_length}"
                    height="${finger_tip_height}">
        <origin xyz="${finger_tip_com}" rpy="0 0 0"/>
        </xacro:link_box_inertial>

        <visual>
            <origin xyz="0 0 0" rpy="0 0 0"/>
            <geometry>
                <mesh filename="file://$(find oberon7_description)/meshes/parallel_gripper/visual/FingerTip.dae"/>
            </geometry>
        </visual>

        <collision>
            <origin xyz="0 0 0" rpy="0 0 0"/>
            <geometry>
                <mesh filename="file://$(find oberon7_description)/meshes/parallel_gripper/visual/FingerTip.dae"/>
            </geometry>
        </collision>
    </link>

    <joint name="${namespace}/finger_tip_left_joint" type="revolute">
        <parent link="${namespace}/finger_left"/>
        <child link="${namespace}/finger_tip_left"/>
        <origin xyz="0.06431 0 0" rpy="${PI} 0 0"/>
        <axis xyz="0 0 1"/>
        <dynamics damping="5" friction="10"/>
        <limit effort="0" lower="0" upper="0" velocity="0"/>
    </joint>

    <!-- Finger right  -->

    <link name="${namespace}/finger_right">
        <xacro:link_box_inertial mass="${total_mass * finger_volume / total_volume}"
                    width="${finger_width}"
                    length="${finger_length}"
                    height="${finger_height}">
        <origin xyz="${finger_com}" rpy="0 0 0"/>
        </xacro:link_box_inertial>

        <visual>
            <origin xyz="0 0 0" rpy="${PI} 0 0"/>
            <geometry>
                <mesh filename="file://$(find oberon7_description)/meshes/parallel_gripper/visual/Finger.dae"/>
            </geometry>
        </visual>

        <collision>
            <origin xyz="0 0 0" rpy="${PI} 0 0"/>
            <geometry>
                <mesh filename="file://$(find oberon7_description)/meshes/parallel_gripper/visual/Finger.dae"/>
            </geometry>
        </collision>
    </link>

    <joint name="${namespace}/finger_right_joint" type="revolute">
        <parent link="${namespace}/end_effector"/>
        <child link="${namespace}/finger_right"/>
        <origin xyz="0.0444267 -0.0391376 0" rpy="${PI} ${PI} ${PI}"/>
        <axis xyz="0 0 -1"/>
        <dynamics damping="5" friction="10"/>
        <limit effort="${gripper_effort}" lower="0" upper="${PI*0.3333}" velocity="${gripper_velocity}"/>
    </joint>

    <xacro:simple_transmission joint="${namespace}/finger_right_joint" />

    <!-- Finger tip right  -->

    <link name="${namespace}/finger_tip_right">
        <xacro:link_box_inertial mass="${total_mass * finger_tip_volume / total_volume}"
                    width="${finger_tip_width}"
                    length="${finger_tip_length}"
                    height="${finger_tip_height}">
        <origin xyz="${finger_tip_com}" rpy="0 0 0"/>
        </xacro:link_box_inertial>

        <visual>
            <origin xyz="0 0 0" rpy="0 0 0"/>
            <geometry>
                <mesh filename="file://$(find oberon7_description)/meshes/parallel_gripper/visual/FingerTip.dae"/>
            </geometry>
        </visual>

        <collision>
            <origin xyz="0 0 0" rpy="0 0 0"/>
            <geometry>
                <mesh filename="file://$(find oberon7_description)/meshes/parallel_gripper/visual/FingerTip.dae"/>
            </geometry>
        </collision>
    </link>

    <joint name="${namespace}/finger_tip_right_joint" type="revolute">
        <parent link="${namespace}/finger_right"/>
        <child link="${namespace}/finger_tip_right"/>
        <origin xyz="0.06431 0 0" rpy="0 0 0"/>
        <axis xyz="0 0 1"/>
        <dynamics damping="5" friction="10"/>
        <limit effort="0" lower="0" upper="0" velocity="0"/>
    </joint>

</robot>
