<?xml version="1.0"?>
<!-- Copyright (c) 2016 The UUV Simulator Authors.
     All rights reserved.

     Licensed under the Apache License, Version 2.0 (the "License");
     you may not use this file except in compliance with the License.
     You may obtain a copy of the License at

       http://www.apache.org/licenses/LICENSE-2.0

     Unless required by applicable law or agreed to in writing, software
     distributed under the License is distributed on an "AS IS" BASIS,
     WITHOUT WARRANTIES OR CONDITIONS OF ANY KIND, either express or implied.
     See the License for the specific language governing permissions and
     limitations under the License.
-->

<robot xmlns:xacro="http://www.ros.org/wiki/xacro">
  <!--
      The RexROV meshes and hydrodynamic parameters are based on the parameters and dimensions
      from the SF 30k.

      References:
        [1] Dukan, Fredrik. "ROV Motion Control Systems." PhD Thesis, NTNU, 2014.
        [2] Berg, Viktor. Development and Commissioning of a DP system for ROV SF 30k. MS
            thesis. Institutt for marin teknikk, 2012.
  -->
  <!-- includes -->
  <xacro:include filename="$(find uuv_descriptions)/models/common/urdf/common.urdf.xacro"/>
  <xacro:include filename="$(find uuv_sensor_plugins_ros)/urdf/sensor_snippets.xacro"/>

  <!-- Parameters -->
  <xacro:property name="namespace" value="rexrov"/>
  <xacro:property name="visual_mesh_file" value="file://$(find uuv_descriptions)/models/rexrov/mesh/RexROV_no_props.dae"/>
  <xacro:property name="prop_mesh_file" value="file://$(find uuv_descriptions)/models/rexrov/mesh/prop.dae"/>

  <!-- Mass, see p.28 in Berg2012 -->
  <xacro:property name="mass" value="1862.87"/>

  <!-- Thruster joint and link snippet -->
  <xacro:macro name="thruster_macro"
               params="namespace thruster_id *origin">
    <joint name="${namespace}/thruster_${thruster_id}_joint" type="continuous">
      <xacro:insert_block name="origin"/>
      <axis xyz="1 0 0"/>
      <parent link="${namespace}/base_link"/>
      <child link="${namespace}/thruster_${thruster_id}"/>
    </joint>
    <link name="${namespace}/thruster_${thruster_id}">
      <xacro:box_inertial x="0" y="0" z="0" mass="0.001">
        <origin xyz="0 0 0" rpy="0 0 0"/>
      </xacro:box_inertial>
      <visual>
        <origin rpy="0 0 0" xyz="0 0 0"/>
        <geometry>
          <mesh filename="${prop_mesh_file}" scale="1 1 1"/>
        </geometry>
      </visual>
      <collision>
        <!-- todo: gazebo needs a collision volume or it will ignore the pose of
           the joint that leads to this link (and assume it to be the identity) -->
        <geometry>
          <cylinder length="0.000001" radius="0.000001"/>
        </geometry>
        <origin xyz="0 0 0" rpy="0 ${0.5*pi} 0"/>
      </collision>
    </link>
    <gazebo>
      <plugin name="${namespace}_${thruster_id}_thruster_model" filename="libthruster_ros_plugin.so">
        <linkName>${namespace}/thruster_${thruster_id}</linkName>
        <jointName>${namespace}/thruster_${thruster_id}_joint</jointName>
        <thrusterID>${thruster_id}</thrusterID>
        <dynamics>
          <type>FirstOrder</type>
          <timeConstant>0.05</timeConstant>
        </dynamics>
        <conversion>
          <type>Basic</type>
          <rotorConstant>0.00031</rotorConstant>
        </conversion>
      </plugin>
    </gazebo>
  </xacro:macro>

  <xacro:macro name="rexrov_base" params="namespace *gazebo">
    <!-- base_link according to ROS conventions: x forward, z up -->
    <link name="${namespace}/base_link">
      <inertial>
        <mass value="${mass}"/>
        <origin xyz="0 0 0"/>
        <inertia ixx="525.39" ixy="1.44" ixz="33.41" iyy="794.20" iyz="2.6" izz="691.23"/>
      </inertial>
      <visual>
        <origin xyz="0 0 0" rpy="0 0 0"/>
        <geometry>
          <mesh filename="${visual_mesh_file}" scale="1 1 1"/>
        </geometry>
      </visual>
      <!-- bottom plate -->
      <collision>
        <origin xyz="0 0 -0.75" rpy="0 0 0"/>
        <geometry>
          <box size="2.56 1.50 0.10"/>
        </geometry>
      </collision>
      <!-- top plate -->
      <collision>
        <origin xyz="0 0 0.60" rpy="0 0 0"/>
        <geometry><box size="2.56 1.50 0.40"/></geometry>
      </collision>
      <!-- left / right sides -->
      <collision>
        <origin xyz="-0.20 0.70 -0.15" rpy="0 0 0"/>
        <geometry><box size="2.20 0.10 1.10"/></geometry>
      </collision>
      <collision>
        <origin xyz="-0.20 -0.70 -0.15" rpy="0 0 0"/>
        <geometry><box size="2.20 0.10 1.10"/></geometry>
      </collision>

    </link>

    <xacro:dummy_link name="${namespace}/ned_link" />

    <joint name="ned_joint" type="fixed">
      <!-- This is revolute and not static since gazebo would remove ned_link -->
      <origin xyz="0 0 0" rpy="${pi} 0 0"/>
      <parent link="${namespace}/base_link"/>
      <child link="${namespace}/ned_link"/>
      <limit effort="0" lower="0" upper="0" velocity="0"/>
    </joint>

    <!-- Set up hydrodynamic plugin given as input parameter -->
    <xacro:insert_block name="gazebo"/>

    <gazebo>
      <!-- optional: plugin to test compare Gazebo's returned accelerations
      <plugin name="${namespace}_test_plugin" filename="libaccelerations_test_plugin.so">
        <link_name>${namespace}/base_link</link_name>
      </plugin> -->
    </gazebo>

    <xacro:thruster_macro namespace="${namespace}" thruster_id="0">
      <origin xyz="-0.890895 0.334385 0.528822" rpy="${0*d2r} ${-74.53*d2r} ${-53.21*d2r}"/>
    </xacro:thruster_macro>
    <xacro:thruster_macro namespace="${namespace}" thruster_id="1">
      <origin xyz="-0.890895 -0.334385 0.528822" rpy="${0*d2r} ${-74.53*d2r} ${53.21*d2r}"/>
    </xacro:thruster_macro>
    <xacro:thruster_macro namespace="${namespace}" thruster_id="2">
      <origin xyz="0.890895 0.334385 0.528822" rpy="${0*d2r} ${-105.47*d2r} ${53.21*d2r}"/>
    </xacro:thruster_macro>
    <xacro:thruster_macro namespace="${namespace}" thruster_id="3">
      <origin xyz="0.890895 -0.334385 0.528822" rpy="${0*d2r} ${-105.47*d2r} ${-53.21*d2r}"/>
    </xacro:thruster_macro>
    <xacro:thruster_macro namespace="${namespace}" thruster_id="4">
      <origin xyz="-0.412125 0.505415 0.129" rpy="${0*d2r} ${0*d2r} ${45*d2r}"/>
    </xacro:thruster_macro>
    <xacro:thruster_macro namespace="${namespace}" thruster_id="5">
      <origin xyz="-0.412125 -0.505415 0.129" rpy="${0*d2r} ${0*d2r} ${-45*d2r}"/>
    </xacro:thruster_macro>
    <xacro:thruster_macro namespace="${namespace}" thruster_id="6">
      <origin xyz="0.412125 0.505415 0.129" rpy="${0*d2r} ${0*d2r} ${135*d2r}"/>
    </xacro:thruster_macro>
    <xacro:thruster_macro namespace="${namespace}" thruster_id="7">
      <origin xyz="0.412125 -0.505415 0.129" rpy="${0*d2r} ${0*d2r} ${-135*d2r}"/>
    </xacro:thruster_macro>

    <!-- Mount a 3D pose sensor -->
    <link name="${namespace}/pose_sensor_link">
      <xacro:box_inertial x="0" y="0" z="0" mass="0.01">
        <origin xyz="0 0 0" rpy="0 0 0"/>
      </xacro:box_inertial>
      <visual>
        <geometry>
          <box size="0.1 0.1 0.1"/>
        </geometry>
      </visual>
      <xacro:no_collision/>
    </link>

    <joint name="${namespace}/pose_sensor_joint" type="revolute">
      <origin xyz="0 0 0" rpy="0 0 0"/>
      <axis xyz="0 0 1"/>
      <parent link="${namespace}/base_link"/>
      <child link="${namespace}/pose_sensor_link"/>
      <limit effort="0" lower="0" upper="0" velocity="0"/>
    </joint>

    <gazebo>
      <plugin name="pose_3d_plugin" filename="libgazebo_ros_p3d.so">
        <robotNamespace>${namespace}</robotNamespace>
        <bodyName>${namespace}/base_link</bodyName>
        <topicName>pose_gt</topicName>
        <frameName>world</frameName>
        <gaussianNoise>0.0</gaussianNoise>
        <updateRate>30</updateRate>
      </plugin>
    </gazebo>

    <!-- DVL  -->
    <xacro:default_dvl namespace="${namespace}" parent_link="${namespace}/base_link">
      <origin xyz="-1.4 0 -0.312" rpy="0 ${0.5*pi} 0"/>
    </xacro:default_dvl>

    <!-- RPT  -->
    <xacro:default_rpt namespace="${namespace}" parent_link="${namespace}/base_link">
      <origin xyz="-1.32 0 0.8" rpy="0 0 0"/>
    </xacro:default_rpt>

    <!-- Pressure  -->
    <xacro:default_pressure namespace="${namespace}" parent_link="${namespace}/base_link">
      <origin xyz="-1.32 0.5 0.85" rpy="0 0 0"/>
    </xacro:default_pressure>

    <!-- IMU  -->
    <xacro:default_imu namespace="${namespace}" parent_link="${namespace}/base_link">
      <origin xyz="0 0 0" rpy="0 0 0"/>
    </xacro:default_imu>

    <!-- Mount a camera -->
    <xacro:default_camera namespace="${namespace}" parent_link="${namespace}/base_link">
      <origin xyz="1.15 0 0.4" rpy="0 0.6 0"/>
    </xacro:default_camera>

    <!-- Mount a GPS. -->
    <xacro:default_gps namespace="${namespace}" parent_link="${namespace}/base_link" />

  </xacro:macro>
</robot>
