<sdf version='1.6'>
  <model name='oberon7'>
    <link name='/base'>
      <pose frame=''>0 0 1.5 0 -0 0</pose>
      <inertial>
        <pose frame=''>-0.101581 -0.001371 -0.009781 0 -0 0</pose>
        <mass>9.67468</mass>
        <inertia>
          <ixx>0.0511732</ixx>
          <ixy>0</ixy>
          <ixz>0</ixz>
          <iyy>0.0836772</iyy>
          <iyz>0</iyz>
          <izz>0.0958033</izz>
        </inertia>
      </inertial>
      <collision name='/base_collision'>
        <pose frame=''>0 0 0 0 -0 0</pose>
        <geometry>
          <mesh>
            <scale>1 1 1</scale>
            <uri>file:///home/mam0box/catkin_ws/src/uuv_simulator/uuv_manipulators/oberon7/oberon7_description/meshes/serial_arm/collision/Base.stl</uri>
          </mesh>
        </geometry>
        <surface>
          <contact>
            <ode/>
          </contact>
          <friction>
            <ode/>
          </friction>
        </surface>
        <max_contacts>1</max_contacts>
      </collision>
      <visual name='/base_visual'>
        <pose frame=''>0 0 0 0 -0 0</pose>
        <geometry>
          <mesh>
            <scale>1 1 1</scale>
            <uri>file:///home/mam0box/catkin_ws/src/uuv_simulator/uuv_manipulators/oberon7/oberon7_description/meshes/serial_arm/visual/Base.dae</uri>
          </mesh>
        </geometry>
        <material>
          <script>
            <uri>__default__</uri>
            <name>__default__</name>
          </script>
        </material>
      </visual>
      <gravity>1</gravity>
      <velocity_decay/>
      <self_collide>0</self_collide>
    </link>
    <joint name='/anchor' type='revolute'>
      <child>/base</child>
      <parent>world</parent>
      <axis>
        <xyz>0 1 0</xyz>
        <limit>
          <lower>0</lower>
          <upper>0</upper>
          <effort>0</effort>
          <velocity>0</velocity>
        </limit>
        <dynamics>
          <spring_reference>0</spring_reference>
          <spring_stiffness>0</spring_stiffness>
        </dynamics>
        <use_parent_model_frame>1</use_parent_model_frame>
      </axis>
    </joint>
    <link name='/shoulder_link'>
      <pose frame=''>0 0 1.5 0 -0 0</pose>
      <inertial>
        <pose frame=''>0.03967 0.005441 0.017383 0 -0 0</pose>
        <mass>6.72225</mass>
        <inertia>
          <ixx>0.042584</ixx>
          <ixy>0</ixy>
          <ixz>0</ixz>
          <iyy>0.0513258</iyy>
          <iyz>0</iyz>
          <izz>0.0295765</izz>
        </inertia>
      </inertial>
      <collision name='/shoulder_link_collision'>
        <pose frame=''>0.03967 0.005441 0.017383 0 -0 0</pose>
        <geometry>
          <cylinder>
            <length>0.239627</length>
            <radius>0.068184</radius>
          </cylinder>
        </geometry>
        <surface>
          <contact>
            <ode/>
          </contact>
          <friction>
            <ode/>
          </friction>
        </surface>
        <max_contacts>1</max_contacts>
      </collision>
      <visual name='/shoulder_link_visual'>
        <pose frame=''>0 0 0 0 -0 0</pose>
        <geometry>
          <mesh>
            <scale>1 1 1</scale>
            <uri>file:///home/mam0box/catkin_ws/src/uuv_simulator/uuv_manipulators/oberon7/oberon7_description/meshes/serial_arm/visual/ShoulderLink.dae</uri>
          </mesh>
        </geometry>
        <material>
          <script>
            <uri>__default__</uri>
            <name>__default__</name>
          </script>
        </material>
      </visual>
      <gravity>1</gravity>
      <velocity_decay/>
      <self_collide>0</self_collide>
    </link>
    <joint name='/azimuth' type='revolute'>
      <child>/shoulder_link</child>
      <parent>/base</parent>
      <axis>
        <xyz>0 0 1</xyz>
        <limit>
          <lower>-1.0472</lower>
          <upper>1.0472</upper>
          <effort>200</effort>
          <velocity>0.17</velocity>
        </limit>
        <dynamics>
          <damping>50</damping>
          <friction>120</friction>
          <spring_reference>0</spring_reference>
          <spring_stiffness>0</spring_stiffness>
        </dynamics>
        <use_parent_model_frame>1</use_parent_model_frame>
      </axis>
    </joint>
    <link name='/upper_arm'>
      <pose frame=''>0.06955 0.00015 1.51536 1.5708 -0 0</pose>
      <inertial>
        <pose frame=''>0.312501 0.017478 -2e-06 0 -0 0</pose>
        <mass>12.4444</mass>
        <inertia>
          <ixx>0.0378234</ixx>
          <ixy>0</ixy>
          <ixz>0</ixz>
          <iyy>0.411488</iyy>
          <iyz>0</iyz>
          <izz>0.415421</izz>
        </inertia>
      </inertial>
      <collision name='/upper_arm_collision'>
        <pose frame=''>0.312501 0.017478 -2e-06 3.14159 1.57079 3.14159</pose>
        <geometry>
          <cylinder>
            <length>0.616809</length>
            <radius>0.0709445</radius>
          </cylinder>
        </geometry>
      </collision>
      <visual name='/upper_arm_visual'>
        <pose frame=''>0 0 0 0 -0 0</pose>
        <geometry>
          <mesh>
            <scale>1 1 1</scale>
            <uri>file:///home/mam0box/catkin_ws/src/uuv_simulator/uuv_manipulators/oberon7/oberon7_description/meshes/serial_arm/visual/UpperArm.dae</uri>
          </mesh>
        </geometry>
      </visual>
    </link>
    <joint name='/shoulder' type='revolute'>
      <child>/upper_arm</child>
      <parent>/shoulder_link</parent>
      <axis>
        <xyz>0 -1 0</xyz>
        <limit>
          <lower>-1.5708</lower>
          <upper>1.5708</upper>
          <effort>5000</effort>
          <velocity>0.17</velocity>
        </limit>
        <dynamics>
          <damping>50</damping>
          <friction>120</friction>
          <spring_reference>0</spring_reference>
          <spring_stiffness>0</spring_stiffness>
        </dynamics>
        <use_parent_model_frame>1</use_parent_model_frame>
      </axis>
    </joint>
    <link name='/elbow_link'>
      <pose frame=''>0.62571 0.00015 1.50307 1.5708 -0 0</pose>
      <inertial>
        <pose frame=''>0.125269 -0.074675 0 0 -0 0</pose>
        <mass>10.3145</mass>
        <inertia>
          <ixx>0.0717198</ixx>
          <ixy>0</ixy>
          <ixz>0</ixz>
          <iyy>0.0724091</iyy>
          <iyz>0</iyz>
          <izz>0.102762</izz>
        </inertia>
      </inertial>
      <collision name='/elbow_link_collision'>
        <pose frame=''>0.125269 -0.074675 0 3.14159 1.57079 -1.57079</pose>
        <geometry>
          <cylinder>
            <length>0.245312</length>
            <radius>0.077562</radius>
          </cylinder>
        </geometry>
        <surface>
          <contact>
            <ode/>
          </contact>
          <friction>
            <ode/>
          </friction>
        </surface>
        <max_contacts>1</max_contacts>
      </collision>
      <visual name='/elbow_link_visual'>
        <pose frame=''>0 0 0 0 -0 0</pose>
        <geometry>
          <mesh>
            <scale>1 1 1</scale>
            <uri>file:///home/mam0box/catkin_ws/src/uuv_simulator/uuv_manipulators/oberon7/oberon7_description/meshes/serial_arm/visual/ElbowLink.dae</uri>
          </mesh>
        </geometry>
        <material>
          <script>
            <uri>__default__</uri>
            <name>__default__</name>
          </script>
        </material>
      </visual>
      <gravity>1</gravity>
      <velocity_decay/>
      <self_collide>0</self_collide>
    </link>
    <joint name='/elbow' type='revolute'>
      <child>/elbow_link</child>
      <parent>/upper_arm</parent>
      <axis>
        <xyz>0 -1 0</xyz>
        <limit>
          <lower>-1.5708</lower>
          <upper>1.0472</upper>
          <effort>300</effort>
          <velocity>0.13</velocity>
        </limit>
        <dynamics>
          <damping>50</damping>
          <friction>120</friction>
          <spring_reference>0</spring_reference>
          <spring_stiffness>0</spring_stiffness>
        </dynamics>
        <use_parent_model_frame>1</use_parent_model_frame>
      </axis>
    </joint>
    <link name='/forearm'>
      <pose frame=''>0.760611 0.00015 1.30944 3.14159 -0 0</pose>
      <inertial>
        <pose frame=''>0 0 0.157979 0 -0 0</pose>
        <mass>8.54626</mass>
        <inertia>
          <ixx>0.0961794</ixx>
          <ixy>0</ixy>
          <ixz>0</ixz>
          <iyy>0.0961902</iyy>
          <iyz>0</iyz>
          <izz>0.032684</izz>
        </inertia>
      </inertial>
      <collision name='/forearm_collision'>
        <pose frame=''>0 0 0.157979 0 -0 0</pose>
        <geometry>
          <cylinder>
            <length>0.334827</length>
            <radius>0.0757275</radius>
          </cylinder>
        </geometry>
        <surface>
          <contact>
            <ode/>
          </contact>
          <friction>
            <ode/>
          </friction>
        </surface>
        <max_contacts>1</max_contacts>
      </collision>
      <visual name='/forearm_visual'>
        <pose frame=''>0 0 0 0 -0 0</pose>
        <geometry>
          <mesh>
            <scale>1 1 1</scale>
            <uri>file:///home/mam0box/catkin_ws/src/uuv_simulator/uuv_manipulators/oberon7/oberon7_description/meshes/serial_arm/visual/Forearm.dae</uri>
          </mesh>
        </geometry>
        <material>
          <script>
            <uri>__default__</uri>
            <name>__default__</name>
          </script>
        </material>
      </visual>
      <gravity>1</gravity>
      <velocity_decay/>
      <self_collide>0</self_collide>
    </link>
    <joint name='/roll' type='revolute'>
      <child>/forearm</child>
      <parent>/elbow_link</parent>
      <axis>
        <xyz>0 -0 -1</xyz>
        <limit>
          <lower>-2.35619</lower>
          <upper>2.35619</upper>
          <effort>200</effort>
          <velocity>0.085</velocity>
        </limit>
        <dynamics>
          <damping>50</damping>
          <friction>120</friction>
          <spring_reference>0</spring_reference>
          <spring_stiffness>0</spring_stiffness>
        </dynamics>
        <use_parent_model_frame>1</use_parent_model_frame>
      </axis>
    </joint>
    <link name='/wrist_link'>
      <pose frame=''>0.760611 0.00015 0.993486 -2.67794 1.57079 2.03445</pose>
      <inertial>
        <pose frame=''>0.104016 0.003308 -2.7e-05 0 -0 0</pose>
        <mass>3.90242</mass>
        <inertia>
          <ixx>0.0104282</ixx>
          <ixy>0</ixy>
          <ixz>0</ixz>
          <iyy>0.0211537</iyy>
          <iyz>0</iyz>
          <izz>0.0205267</izz>
        </inertia>
      </inertial>
      <collision name='/wrist_link_collision'>
        <pose frame=''>0.104016 0.003308 -2.7e-05 3.14159 1.57079 3.14159</pose>
        <geometry>
          <cylinder>
            <length>0.219204</length>
            <radius>0.065187</radius>
          </cylinder>
        </geometry>
        <surface>
          <contact>
            <ode/>
          </contact>
          <friction>
            <ode/>
          </friction>
        </surface>
        <max_contacts>1</max_contacts>
      </collision>
      <visual name='/wrist_link_visual'>
        <pose frame=''>0 0 0 0 -0 0</pose>
        <geometry>
          <mesh>
            <scale>1 1 1</scale>
            <uri>file:///home/mam0box/catkin_ws/src/uuv_simulator/uuv_manipulators/oberon7/oberon7_description/meshes/serial_arm/visual/Wrist.dae</uri>
          </mesh>
        </geometry>
        <material>
          <script>
            <uri>__default__</uri>
            <name>__default__</name>
          </script>
        </material>
      </visual>
      <gravity>1</gravity>
      <velocity_decay/>
      <self_collide>0</self_collide>
    </link>
    <joint name='/pitch' type='revolute'>
      <child>/wrist_link</child>
      <parent>/forearm</parent>
      <axis>
        <xyz>-0 -1 0</xyz>
        <limit>
          <lower>-1.5708</lower>
          <upper>1.5708</upper>
          <effort>200</effort>
          <velocity>0.26</velocity>
        </limit>
        <dynamics>
          <damping>50</damping>
          <friction>120</friction>
          <spring_reference>0</spring_reference>
          <spring_stiffness>0</spring_stiffness>
        </dynamics>
        <use_parent_model_frame>1</use_parent_model_frame>
      </axis>
    </joint>
    <link name='/end_effector'>
      <pose frame=''>0.760611 0.00015 0.800446 -2.67794 1.57079 2.03445</pose>
      <inertial>
        <pose frame=''>0.024426 -0 -1.4e-05 0 -0 0</pose>
        <mass>3.46115</mass>
        <inertia>
          <ixx>0.00774522</ixx>
          <ixy>0</ixy>
          <ixz>0</ixz>
          <iyy>0.00536143</iyy>
          <iyz>0</iyz>
          <izz>0.00557056</izz>
        </inertia>
      </inertial>
      <collision name='/end_effector_collision'>
        <pose frame=''>0.024426 -0 -1.4e-05 0 -0 0</pose>
        <geometry>
          <box>
            <size>0.074326 0.117427 0.114298</size>
          </box>
        </geometry>
      </collision>
      <visual name='/end_effector_visual'>
        <pose frame=''>0 0 0 0 -0 0</pose>
        <geometry>
          <mesh>
            <scale>1 1 1</scale>
            <uri>file:///home/mam0box/catkin_ws/src/uuv_simulator/uuv_manipulators/oberon7/oberon7_description/meshes/parallel_gripper/visual/BaseGripper.dae</uri>
          </mesh>
        </geometry>
      </visual>
    </link>
    <joint name='/wrist' type='revolute'>
      <child>/end_effector</child>
      <parent>/wrist_link</parent>
      <axis>
        <xyz>0 -0 -1</xyz>
        <limit>
          <lower>-1e+16</lower>
          <upper>1e+16</upper>
        </limit>
        <dynamics>
          <damping>10</damping>
          <friction>5</friction>
          <spring_reference>0</spring_reference>
          <spring_stiffness>0</spring_stiffness>
        </dynamics>
        <use_parent_model_frame>1</use_parent_model_frame>
      </axis>
    </joint>
    <link name='/finger_left'>
      <pose frame=''>0.799749 0.00015 0.756019 -2.67794 1.57079 2.03445</pose>
      <inertial>
        <pose frame=''>0.025268 -0.001931 -7.9e-05 0 -0 0</pose>
        <mass>0.879771</mass>
        <inertia>
          <ixx>0.000378331</ixx>
          <ixy>0</ixy>
          <ixz>0</ixz>
          <iyy>0.000886148</iyy>
          <iyz>0</iyz>
          <izz>0.000919231</izz>
        </inertia>
      </inertial>
      <collision name='/finger_left_collision'>
        <pose frame=''>0 0 0 0 -0 0</pose>
        <geometry>
          <mesh>
            <scale>1 1 1</scale>
            <uri>file:///home/mam0box/catkin_ws/src/uuv_simulator/uuv_manipulators/oberon7/oberon7_description/meshes/parallel_gripper/visual/Finger.dae</uri>
          </mesh>
        </geometry>
        <surface>
          <contact>
            <ode>
              <kp>1e+06</kp>
              <kd>1</kd>
              <min_depth>0.001</min_depth>
            </ode>
          </contact>
          <friction>
            <ode>
              <mu>1</mu>
              <mu2>1</mu2>
            </ode>
          </friction>
        </surface>
        <max_contacts>1</max_contacts>
      </collision>
      <visual name='/finger_left_visual'>
        <pose frame=''>0 0 0 0 -0 0</pose>
        <geometry>
          <mesh>
            <scale>1 1 1</scale>
            <uri>file:///home/mam0box/catkin_ws/src/uuv_simulator/uuv_manipulators/oberon7/oberon7_description/meshes/parallel_gripper/visual/Finger.dae</uri>
          </mesh>
        </geometry>
        <material>
          <script>
            <uri>__default__</uri>
            <name>__default__</name>
          </script>
        </material>
      </visual>
      <gravity>1</gravity>
      <velocity_decay/>
      <self_collide>0</self_collide>
    </link>
    <joint name='/finger_left_joint' type='revolute'>
      <child>/finger_left</child>
      <parent>/end_effector</parent>
      <axis>
        <xyz>-0 -1 0</xyz>
        <limit>
          <lower>0</lower>
          <upper>1.04709</upper>
          <effort>30</effort>
          <velocity>0.15</velocity>
        </limit>
        <dynamics>
          <damping>5</damping>
          <friction>10</friction>
          <spring_reference>0</spring_reference>
          <spring_stiffness>0</spring_stiffness>
        </dynamics>
        <use_parent_model_frame>1</use_parent_model_frame>
      </axis>
    </joint>
    <link name='/finger_tip_left'>
      <pose frame=''>0.799749 0.00015 0.691709 0.463653 1.57079 2.03444</pose>
      <inertial>
        <pose frame=''>0.027744 0.017278 0 0 -0 0</pose>
        <mass>1.12551</mass>
        <inertia>
          <ixx>0.000611047</ixx>
          <ixy>0</ixy>
          <ixz>0</ixz>
          <iyy>0.00134903</iyy>
          <iyz>0</iyz>
          <izz>0.00121556</izz>
        </inertia>
      </inertial>
      <collision name='/finger_tip_left_collision'>
        <pose frame=''>0 0 0 0 -0 0</pose>
        <geometry>
          <mesh>
            <scale>1 1 1</scale>
            <uri>file:///home/mam0box/catkin_ws/src/uuv_simulator/uuv_manipulators/oberon7/oberon7_description/meshes/parallel_gripper/visual/FingerTip.dae</uri>
          </mesh>
        </geometry>
        <surface>
          <contact>
            <ode>
              <kp>1e+06</kp>
              <kd>1</kd>
              <min_depth>0.001</min_depth>
            </ode>
          </contact>
          <friction>
            <ode>
              <mu>1</mu>
              <mu2>1</mu2>
            </ode>
          </friction>
        </surface>
        <max_contacts>3</max_contacts>
      </collision>
      <visual name='/finger_tip_left_visual'>
        <pose frame=''>0 0 0 0 -0 0</pose>
        <geometry>
          <mesh>
            <scale>1 1 1</scale>
            <uri>file:///home/mam0box/catkin_ws/src/uuv_simulator/uuv_manipulators/oberon7/oberon7_description/meshes/parallel_gripper/visual/FingerTip.dae</uri>
          </mesh>
        </geometry>
        <material>
          <script>
            <uri>__default__</uri>
            <name>__default__</name>
          </script>
        </material>
      </visual>
      <gravity>1</gravity>
      <velocity_decay/>
      <self_collide>1</self_collide>
    </link>
    <joint name='/finger_tip_left_joint' type='revolute'>
      <child>/finger_tip_left</child>
      <parent>/finger_left</parent>
      <axis>
        <xyz>0 1 -0</xyz>
        <limit>
          <lower>0</lower>
          <upper>0</upper>
          <effort>0</effort>
          <velocity>0</velocity>
        </limit>
        <dynamics>
          <damping>5</damping>
          <friction>10</friction>
          <spring_reference>0</spring_reference>
          <spring_stiffness>0</spring_stiffness>
        </dynamics>
        <use_parent_model_frame>1</use_parent_model_frame>
      </axis>
    </joint>
    <link name='/finger_right'>
      <pose frame=''>0.721474 0.00015 0.756019 -2.6697 1.57079 2.04268</pose>
      <inertial>
        <pose frame=''>0.025268 -0.001931 -7.9e-05 0 -0 0</pose>
        <mass>0.879771</mass>
        <inertia>
          <ixx>0.000378331</ixx>
          <ixy>0</ixy>
          <ixz>0</ixz>
          <iyy>0.000886148</iyy>
          <iyz>0</iyz>
          <izz>0.000919231</izz>
        </inertia>
      </inertial>
      <collision name='/finger_right_collision'>
        <pose frame=''>0 0 0 -3.14159 -0 0</pose>
        <geometry>
          <mesh>
            <scale>1 1 1</scale>
            <uri>file:///home/mam0box/catkin_ws/src/uuv_simulator/uuv_manipulators/oberon7/oberon7_description/meshes/parallel_gripper/visual/Finger.dae</uri>
          </mesh>
        </geometry>
        <surface>
          <contact>
            <ode>
              <kp>1e+06</kp>
              <kd>1</kd>
              <min_depth>0.001</min_depth>
            </ode>
          </contact>
          <friction>
            <ode>
              <mu>1</mu>
              <mu2>1</mu2>
            </ode>
          </friction>
        </surface>
        <max_contacts>1</max_contacts>
      </collision>
      <visual name='/finger_right_visual'>
        <pose frame=''>0 0 0 -3.14159 -0 0</pose>
        <geometry>
          <mesh>
            <scale>1 1 1</scale>
            <uri>file:///home/mam0box/catkin_ws/src/uuv_simulator/uuv_manipulators/oberon7/oberon7_description/meshes/parallel_gripper/visual/Finger.dae</uri>
          </mesh>
        </geometry>
        <material>
          <script>
            <uri>__default__</uri>
            <name>__default__</name>
          </script>
        </material>
      </visual>
      <gravity>1</gravity>
      <velocity_decay/>
      <self_collide>0</self_collide>
    </link>
    <joint name='/finger_right_joint' type='revolute'>
      <child>/finger_right</child>
      <parent>/end_effector</parent>
      <axis>
        <xyz>0 1 -0</xyz>
        <limit>
          <lower>0</lower>
          <upper>1.04709</upper>
          <effort>30</effort>
          <velocity>0.15</velocity>
        </limit>
        <dynamics>
          <damping>5</damping>
          <friction>10</friction>
          <spring_reference>0</spring_reference>
          <spring_stiffness>0</spring_stiffness>
        </dynamics>
        <use_parent_model_frame>1</use_parent_model_frame>
      </axis>
    </joint>
    <link name='/finger_tip_right'>
      <pose frame=''>0.721474 0.00015 0.691709 -2.6697 1.57079 2.04268</pose>
      <inertial>
        <pose frame=''>0.027744 0.017278 0 0 -0 0</pose>
        <mass>1.12551</mass>
        <inertia>
          <ixx>0.000611047</ixx>
          <ixy>0</ixy>
          <ixz>0</ixz>
          <iyy>0.00134903</iyy>
          <iyz>0</iyz>
          <izz>0.00121556</izz>
        </inertia>
      </inertial>
      <collision name='/finger_tip_right_collision'>
        <pose frame=''>0 0 0 0 -0 0</pose>
        <geometry>
          <mesh>
            <scale>1 1 1</scale>
            <uri>file:///home/mam0box/catkin_ws/src/uuv_simulator/uuv_manipulators/oberon7/oberon7_description/meshes/parallel_gripper/visual/FingerTip.dae</uri>
          </mesh>
        </geometry>
        <surface>
          <contact>
            <ode>
              <kp>1e+06</kp>
              <kd>1</kd>
              <min_depth>0.001</min_depth>
            </ode>
          </contact>
          <friction>
            <ode>
              <mu>1</mu>
              <mu2>1</mu2>
            </ode>
          </friction>
        </surface>
        <max_contacts>3</max_contacts>
      </collision>
      <visual name='/finger_tip_right_visual'>
        <pose frame=''>0 0 0 0 -0 0</pose>
        <geometry>
          <mesh>
            <scale>1 1 1</scale>
            <uri>file:///home/mam0box/catkin_ws/src/uuv_simulator/uuv_manipulators/oberon7/oberon7_description/meshes/parallel_gripper/visual/FingerTip.dae</uri>
          </mesh>
        </geometry>
        <material>
          <script>
            <uri>__default__</uri>
            <name>__default__</name>
          </script>
        </material>
      </visual>
      <gravity>1</gravity>
      <velocity_decay/>
      <self_collide>1</self_collide>
    </link>
    <joint name='/finger_tip_right_joint' type='revolute'>
      <child>/finger_tip_right</child>
      <parent>/finger_right</parent>
      <axis>
        <xyz>-0 -1 0</xyz>
        <limit>
          <lower>0</lower>
          <upper>0</upper>
          <effort>0</effort>
          <velocity>0</velocity>
        </limit>
        <dynamics>
          <damping>5</damping>
          <friction>10</friction>
          <spring_reference>0</spring_reference>
          <spring_stiffness>0</spring_stiffness>
        </dynamics>
        <use_parent_model_frame>1</use_parent_model_frame>
      </axis>
    </joint>
  </model>
</sdf>
