<?xml version="1.0" ?>
<!-- =================================================================================== -->
<!-- |    This document was autogenerated by xacro from /home/mam0box/catkin_ws/src/uuv_simulator/uuv_manipulators/oberon7/oberon7_description/robots/oberon7_standalone.xacro | -->
<!-- |    EDITING THIS FILE BY HAND IS NOT RECOMMENDED                                 | -->
<!-- =================================================================================== -->
<!-- Copyright (c) 2016 The UUV Simulator Authors.
     All rights reserved.

     Licensed under the Apache License, Version 2.0 (the "License");
     you may not use this file except in compliance with the License.
     You may obtain a copy of the License at

       http://www.apache.org/licenses/LICENSE-2.0

     Unless required by applicable law or agreed to in writing, software
     distributed under the License is distributed on an "AS IS" BASIS,
     WITHOUT WARRANTIES OR CONDITIONS OF ANY KIND, either express or implied.
     See the License for the specific language governing permissions and
     limitations under the License.
-->
<robot name="oberon7" xmlns:xacro="http://www.ros.org/wiki/xacro">
  <!--
    GRIPPER BASE

    Mesh Bounding Box Size 0.074326 0.117427 0.114298
    Mesh Bounding Box Diag 0.179938 
    Mesh Volume is 0.000699
    Mesh Surface is 0.160112
    Thin shell barycenter 0.025369 -0.000000 -0.000018
    Center of Mass is 0.024426 -0.000000 -0.000014
  -->
  <!--  
    FINGER

    Mesh Bounding Box Size 0.098653 0.052970 0.048524
    Mesh Bounding Box Diag 0.122036 
    Mesh Volume is 0.000209
    Mesh Surface is 0.034727
    Thin shell barycenter 0.030139 -0.002041 -0.000073
    Center of Mass is 0.025268 -0.001931 -0.000079
  -->
  <!--  
    FINGER TIP

    Mesh Bounding Box Size 0.102050 0.050457 0.063000
    Mesh Bounding Box Diag 0.130112 
    Mesh Volume is 0.000204
    Mesh Surface is 0.054039
    Thin shell barycenter 0.025479 0.015748 -0.000000
    Center of Mass is 0.027744 0.017278 -0.000000
  -->
  <!-- 
    BASE

    Mesh Bounding Box Size 0.282087 0.198133 0.155615
    Mesh Bounding Box Diag 0.378214 
    Mesh Volume is 0.002325
    Mesh Surface is 0.487803
    Thin shell barycenter -0.107470 -0.006304 0.000594
    Center of Mass is -0.101581 -0.001371 -0.009781
    Inertia Tensor is :
    | 0.000009 -0.000001 -0.000000 |
    | -0.000001 0.000021 -0.000000 |
    | -0.000000 -0.000000 0.000016 |
    Principal axes are :
    | 0.997501 -0.064601 -0.028597 |
    | 0.064852 0.997864 0.007918 |
    | 0.028024 -0.009753 0.999560 |
    axis momenta are :
    | 0.000008 0.000022 0.000016 |
  -->
  <!--  
    SHOULDER_LINK

    Mesh Bounding Box Size 0.184936 0.136368 0.239627
    Mesh Bounding Box Diag 0.331992 
    Mesh Volume is 0.001429
    Mesh Surface is 0.288886
    Thin shell barycenter 0.036609 0.005679 0.020522
    Center of Mass is 0.039670 0.005441 0.017383
    Inertia Tensor is :
    | 0.000005 0.000000 0.000001 |
    | 0.000000 0.000006 0.000000 |
    | 0.000001 0.000000 0.000004 |
    Principal axes are :
    | 0.560392 0.683266 -0.468091 |
    | -0.763732 0.644964 0.027116 |
    | 0.320429 0.342300 0.883264 |
    axis momenta are :
    | 0.000006 0.000006 0.000003 |
  -->
  <!--  
    UPPER ARM

    Mesh Bounding Box Size 0.616809 0.141889 0.127829
    Mesh Bounding Box Diag 0.645698 
    Mesh Volume is 0.001505
    Mesh Surface is 0.899623
    Thin shell barycenter 0.288444 0.022849 0.000011
    Center of Mass is 0.312501 0.017478 -0.000002
    Inertia Tensor is :
    | 0.000009 0.000013 -0.000000 |
    | 0.000013 0.000053 -0.000000 |
    | -0.000000 -0.000000 0.000051 |
    Principal axes are :
    | 0.966612 0.256246 0.000061 |
    | -0.256246 0.966611 0.000814 |
    | 0.000150 -0.000803 1.000000 |
    axis momenta are :
    | 0.000005 0.000056 0.000051 |
  -->
  <!--  
    ELBOW LINK

    Mesh Bounding Box Size 0.245312 0.243672 0.155124
    Mesh Bounding Box Diag 0.378969 
    Mesh Volume is 0.009154
    Mesh Surface is 0.456305
    Thin shell barycenter 0.097098 -0.063346 0.000000
    Center of Mass is 0.125269 -0.074675 0.000000
    Inertia Tensor is :
    | 0.000054 0.000003 -0.000000 |
    | 0.000003 0.000035 0.000000 |
    | -0.000000 0.000000 0.000063 |
    Principal axes are :
    | 0.984419 -0.175836 -0.000000 |
    | 0.175836 0.984419 -0.000000 |
    | 0.000000 -0.000000 1.000000 |
    axis momenta are :
    | 0.000055 0.000034 0.000063 |
  -->
  <!--   
    FOREARM

    Mesh Bounding Box Size 0.151505 0.151455 0.334827
    Mesh Bounding Box Diag 0.397494 
    Mesh Volume is -nan
    Mesh Surface is 0.520458
    Thin shell barycenter -0.007291 -0.000030 0.122565
  -->
  <!--
    WRIST 

    Mesh Bounding Box Size 0.219204 0.122758 0.130373
    Mesh Bounding Box Diag 0.283049 
    Mesh Volume is 0.003565
    Mesh Surface is 0.539961
    Thin shell barycenter 0.088012 0.005072 0.000117
    Center of Mass is 0.104016 0.003308 -0.000027
    Inertia Tensor is :
    | 0.000008 0.000001 -0.000000 |
    | 0.000001 0.000014 0.000000 |
    | -0.000000 0.000000 0.000013 |
    Principal axes are :
    | 0.991806 0.127750 -0.000505 |
    | -0.127750 0.991806 0.000070 |
    | 0.000510 -0.000005 1.000000 |
    axis momenta are :
    | 0.000008 0.000014 0.000013 |
  -->
  <!-- Inertial macros for all serial arm links  -->
  <link name="world"/>
  <!-- Ground base -->
  <link name="/base">
    <inertial>
      <origin rpy="0 0 0" xyz="-0.101581 -0.001371 -0.009781"/>
      <mass value="9.67467717018"/>
      <inertia ixx="0.0511731678147" ixy="0.0" ixz="0.0" iyy="0.0836771724144" iyz="0.0" izz="0.0958032978152"/>
    </inertial>
    <visual>
      <origin rpy="0 0 0" xyz="0 0 0"/>
      <geometry>
        <mesh filename="file:///home/mam0box/catkin_ws/src/uuv_simulator/uuv_manipulators/oberon7/oberon7_description/meshes/serial_arm/visual/Base.dae"/>
      </geometry>
    </visual>
    <collision>
      <origin rpy="0 0 0" xyz="0 0 0"/>
      <geometry>
        <mesh filename="file:///home/mam0box/catkin_ws/src/uuv_simulator/uuv_manipulators/oberon7/oberon7_description/meshes/serial_arm/collision/Base.stl"/>
      </geometry>
    </collision>
  </link>
  <!-- Shoulder link -->
  <link name="/shoulder_link">
    <inertial>
      <origin rpy="0 0 0" xyz="0.039670 0.005441 0.017383"/>
      <mass value="6.72225246901"/>
      <inertia ixx="0.0425839738294" ixy="0.0" ixz="0.0" iyy="0.0513257548564" iyz="0.0" izz="0.0295765413777"/>
    </inertial>
    <visual>
      <origin rpy="0 0 0" xyz="0 0 0"/>
      <geometry>
        <mesh filename="file:///home/mam0box/catkin_ws/src/uuv_simulator/uuv_manipulators/oberon7/oberon7_description/meshes/serial_arm/visual/ShoulderLink.dae"/>
      </geometry>
    </visual>
    <collision>
      <origin rpy="0 0 0" xyz="0.039670 0.005441 0.017383"/>
      <geometry>
        <cylinder length="0.239627" radius="0.068184"/>
      </geometry>
    </collision>
  </link>
  <joint name="/azimuth" type="revolute">
    <parent link="/base"/>
    <child link="/shoulder_link"/>
    <axis xyz="0 0 1"/>
    <dynamics damping="50" friction="120"/>
    <limit effort="200" lower="-1.04719758" upper="1.04719758" velocity="0.17"/>
  </joint>
  <transmission name="/azimuth_trans">
    <type>transmission_interface/SimpleTransmission</type>
    <joint name="/azimuth">
      <hardwareInterface>hardware_interface/EffortJointInterface</hardwareInterface>
    </joint>
    <actuator name="/azimuth_motor">
      <hardwareInterface>hardware_interface/EffortJointInterface</hardwareInterface>
      <mechanicalReduction>1</mechanicalReduction>
    </actuator>
  </transmission>
  <!-- UPPER ARM -->
  <link name="/upper_arm">
    <inertial>
      <origin rpy="0 0 0" xyz="0.312501 0.017478 -0.000002"/>
      <mass value="12.4443999072"/>
      <inertia ixx="0.0378234483246" ixy="0.0" ixz="0.0" iyy="0.411488180504" iyz="0.0" izz="0.415420854645"/>
    </inertial>
    <visual>
      <origin rpy="0 0 0" xyz="0 0 0"/>
      <geometry>
        <mesh filename="file:///home/mam0box/catkin_ws/src/uuv_simulator/uuv_manipulators/oberon7/oberon7_description/meshes/serial_arm/visual/UpperArm.dae"/>
      </geometry>
    </visual>
    <collision>
      <origin rpy="0 1.57079632679 0" xyz="0.312501 0.017478 -0.000002"/>
      <geometry>
        <cylinder length="0.616809" radius="0.0709445"/>
      </geometry>
    </collision>
  </link>
  <joint name="/shoulder" type="revolute">
    <parent link="/shoulder_link"/>
    <child link="/upper_arm"/>
    <origin rpy="1.57079632679 0 0" xyz="0.06955 0.00015 0.01536"/>
    <axis xyz="0 0 1"/>
    <dynamics damping="50" friction="120"/>
    <limit effort="5000" lower="-1.57079637" upper="1.57079637" velocity=".17"/>
  </joint>
  <transmission name="/shoulder_trans">
    <type>transmission_interface/SimpleTransmission</type>
    <joint name="/shoulder">
      <hardwareInterface>hardware_interface/EffortJointInterface</hardwareInterface>
    </joint>
    <actuator name="/shoulder_motor">
      <hardwareInterface>hardware_interface/EffortJointInterface</hardwareInterface>
      <mechanicalReduction>1</mechanicalReduction>
    </actuator>
  </transmission>
  <!-- ELBOW LINK -->
  <link name="/elbow_link">
    <inertial>
      <origin rpy="0 0 0" xyz="0.125269 -0.074675 0.0"/>
      <mass value="10.3145088675"/>
      <inertia ixx="0.0717197873733" ixy="0.0" ixz="0.0" iyy="0.0724090834438" iyz="0.0" izz="0.10276175034"/>
    </inertial>
    <visual>
      <origin rpy="0 0 0" xyz="0 0 0"/>
      <geometry>
        <mesh filename="file:///home/mam0box/catkin_ws/src/uuv_simulator/uuv_manipulators/oberon7/oberon7_description/meshes/serial_arm/visual/ElbowLink.dae"/>
      </geometry>
    </visual>
    <collision>
      <origin rpy="0 1.57079632679 1.57079632679" xyz="0.125269 -0.074675 0.0"/>
      <geometry>
        <cylinder length="0.245312" radius="0.077562"/>
      </geometry>
    </collision>
  </link>
  <joint name="/elbow" type="revolute">
    <parent link="/upper_arm"/>
    <child link="/elbow_link"/>
    <origin rpy="0 0 0" xyz="0.55616 -0.01229 0"/>
    <dynamics damping="50" friction="120"/>
    <axis xyz="0 0 1"/>
    <limit effort="300" lower="-1.57079637" upper="1.04719758" velocity=".13"/>
  </joint>
  <transmission name="/elbow_trans">
    <type>transmission_interface/SimpleTransmission</type>
    <joint name="/elbow">
      <hardwareInterface>hardware_interface/EffortJointInterface</hardwareInterface>
    </joint>
    <actuator name="/elbow_motor">
      <hardwareInterface>hardware_interface/EffortJointInterface</hardwareInterface>
      <mechanicalReduction>1</mechanicalReduction>
    </actuator>
  </transmission>
  <!-- FOREARM -->
  <link name="/forearm">
    <inertial>
      <origin rpy="0 0 0" xyz="0 0 0.157978803149"/>
      <mass value="8.54626175585"/>
      <inertia ixx="0.0961794420773" ixy="0.0" ixz="0.0" iyy="0.0961902303084" iyz="0.0" izz="0.0326840256692"/>
    </inertial>
    <visual>
      <origin rpy="0 0 0" xyz="0 0 0"/>
      <geometry>
        <mesh filename="file:///home/mam0box/catkin_ws/src/uuv_simulator/uuv_manipulators/oberon7/oberon7_description/meshes/serial_arm/visual/Forearm.dae"/>
      </geometry>
    </visual>
    <collision>
      <origin rpy="0 0 0" xyz="0 0 0.157978803149"/>
      <geometry>
        <cylinder length="0.334827" radius="0.0757275"/>
      </geometry>
    </collision>
  </link>
  <joint name="/roll" type="revolute">
    <parent link="/elbow_link"/>
    <child link="/forearm"/>
    <origin rpy="1.57079632679 0 0" xyz="0.1349014 -0.1936267 0"/>
    <axis xyz="0 0 1"/>
    <dynamics damping="50" friction="120"/>
    <limit effort="200" lower="-2.356194555" upper="2.356194555" velocity=".085"/>
  </joint>
  <transmission name="/roll_trans">
    <type>transmission_interface/SimpleTransmission</type>
    <joint name="/roll">
      <hardwareInterface>hardware_interface/EffortJointInterface</hardwareInterface>
    </joint>
    <actuator name="/roll_motor">
      <hardwareInterface>hardware_interface/EffortJointInterface</hardwareInterface>
      <mechanicalReduction>1</mechanicalReduction>
    </actuator>
  </transmission>
  <!-- WRIST 1  -->
  <link name="/wrist_link">
    <inertial>
      <origin rpy="0 0 0" xyz="0.104016 0.003308 -0.000027"/>
      <mass value="3.9024235777"/>
      <inertia ixx="0.0104282209379" ixy="0.0" ixz="0.0" iyy="0.0211536636614" iyz="0.0" izz="0.020526721979"/>
    </inertial>
    <visual>
      <origin rpy="0 0 0" xyz="0 0 0"/>
      <geometry>
        <mesh filename="file:///home/mam0box/catkin_ws/src/uuv_simulator/uuv_manipulators/oberon7/oberon7_description/meshes/serial_arm/visual/Wrist.dae"/>
      </geometry>
    </visual>
    <collision>
      <origin rpy="0 1.57079632679 0" xyz="0.104016 0.003308 -0.000027"/>
      <geometry>
        <cylinder length="0.219204" radius="0.065187"/>
      </geometry>
    </collision>
  </link>
  <joint name="/pitch" type="revolute">
    <parent link="/forearm"/>
    <child link="/wrist_link"/>
    <origin rpy="-1.57079632679 -1.57079632679 0" xyz="0 0 0.31595760629823427"/>
    <axis xyz="0 0 1"/>
    <dynamics damping="50" friction="120"/>
    <limit effort="200" lower="-1.57079637" upper="1.57079637" velocity=".26"/>
  </joint>
  <transmission name="/pitch_trans">
    <type>transmission_interface/SimpleTransmission</type>
    <joint name="/pitch">
      <hardwareInterface>hardware_interface/EffortJointInterface</hardwareInterface>
    </joint>
    <actuator name="/pitch_motor">
      <hardwareInterface>hardware_interface/EffortJointInterface</hardwareInterface>
      <mechanicalReduction>1</mechanicalReduction>
    </actuator>
  </transmission>
  <!-- Ground base -->
  <link name="/end_effector">
    <inertial>
      <origin rpy="0 0 0" xyz="0.024426 -0.000000 -0.000014"/>
      <mass value="3.46114581082"/>
      <inertia ixx="0.00774521740658" ixy="0.0" ixz="0.0" iyy="0.00536142648454" iyz="0.0" izz="0.0055705568526"/>
    </inertial>
    <visual>
      <origin rpy="0 0 0" xyz="0 0 0"/>
      <geometry>
        <mesh filename="file:///home/mam0box/catkin_ws/src/uuv_simulator/uuv_manipulators/oberon7/oberon7_description/meshes/parallel_gripper/visual/BaseGripper.dae"/>
      </geometry>
    </visual>
    <collision>
      <origin rpy="0 0 0" xyz="0.024426 -0.000000 -0.000014"/>
      <geometry>
        <box size="0.074326 0.117427 0.114298"/>
      </geometry>
    </collision>
  </link>
  <joint name="/wrist" type="continuous">
    <parent link="/wrist_link"/>
    <child link="/end_effector"/>
    <origin rpy="0 0 0" xyz="0.19304 0 0"/>
    <axis xyz="1 0 0"/>
    <dynamics damping="10" friction="5"/>
  </joint>
  <transmission name="/wrist_trans">
    <type>transmission_interface/SimpleTransmission</type>
    <joint name="/wrist">
      <hardwareInterface>hardware_interface/EffortJointInterface</hardwareInterface>
    </joint>
    <actuator name="/wrist_motor">
      <hardwareInterface>hardware_interface/EffortJointInterface</hardwareInterface>
      <mechanicalReduction>1</mechanicalReduction>
    </actuator>
  </transmission>
  <!-- Finger left  -->
  <link name="/finger_left">
    <inertial>
      <origin rpy="0 0 0" xyz="0.025268 -0.001931 -0.000079"/>
      <mass value="0.879770511849"/>
      <inertia ixx="0.000378330605849" ixy="0.0" ixz="0.0" iyy="0.000886148330217" iyz="0.0" izz="0.00091923080428"/>
    </inertial>
    <visual>
      <origin rpy="0 0 0" xyz="0 0 0"/>
      <geometry>
        <mesh filename="file:///home/mam0box/catkin_ws/src/uuv_simulator/uuv_manipulators/oberon7/oberon7_description/meshes/parallel_gripper/visual/Finger.dae"/>
      </geometry>
    </visual>
    <collision>
      <origin rpy="0 0 0" xyz="0 0 0"/>
      <geometry>
        <mesh filename="file:///home/mam0box/catkin_ws/src/uuv_simulator/uuv_manipulators/oberon7/oberon7_description/meshes/parallel_gripper/visual/Finger.dae"/>
      </geometry>
    </collision>
  </link>
  <joint name="/finger_left_joint" type="revolute">
    <parent link="/end_effector"/>
    <child link="/finger_left"/>
    <origin rpy="0 0 0" xyz="0.0444267 0.0391376 0"/>
    <axis xyz="0 0 1"/>
    <dynamics damping="5" friction="10"/>
    <limit effort="30" lower="0" upper="1.04709283144" velocity="0.15"/>
  </joint>
  <transmission name="/finger_left_joint_trans">
    <type>transmission_interface/SimpleTransmission</type>
    <joint name="/finger_left_joint">
      <hardwareInterface>hardware_interface/EffortJointInterface</hardwareInterface>
    </joint>
    <actuator name="/finger_left_joint_motor">
      <hardwareInterface>hardware_interface/EffortJointInterface</hardwareInterface>
      <mechanicalReduction>1</mechanicalReduction>
    </actuator>
  </transmission>
  <!-- Finger tip left  -->
  <link name="/finger_tip_left">
    <inertial>
      <origin rpy="0 0 0" xyz="0.027744 0.017278 0.0"/>
      <mass value="1.12550524054"/>
      <inertia ixx="0.000611047001819" ixy="0.0" ixz="0.0" iyy="0.00134903081039" iyz="0.0" izz="0.00121555609857"/>
    </inertial>
    <visual>
      <origin rpy="0 0 0" xyz="0 0 0"/>
      <geometry>
        <mesh filename="file:///home/mam0box/catkin_ws/src/uuv_simulator/uuv_manipulators/oberon7/oberon7_description/meshes/parallel_gripper/visual/FingerTip.dae"/>
      </geometry>
    </visual>
    <collision>
      <origin rpy="0 0 0" xyz="0 0 0"/>
      <geometry>
        <mesh filename="file:///home/mam0box/catkin_ws/src/uuv_simulator/uuv_manipulators/oberon7/oberon7_description/meshes/parallel_gripper/visual/FingerTip.dae"/>
      </geometry>
    </collision>
  </link>
  <joint name="/finger_tip_left_joint" type="revolute">
    <parent link="/finger_left"/>
    <child link="/finger_tip_left"/>
    <origin rpy="3.14159265359 0 0" xyz="0.06431 0 0"/>
    <axis xyz="0 0 1"/>
    <dynamics damping="5" friction="10"/>
    <limit effort="0" lower="0" upper="0" velocity="0"/>
  </joint>
  <!-- Finger right  -->
  <link name="/finger_right">
    <inertial>
      <origin rpy="0 0 0" xyz="0.025268 -0.001931 -0.000079"/>
      <mass value="0.879770511849"/>
      <inertia ixx="0.000378330605849" ixy="0.0" ixz="0.0" iyy="0.000886148330217" iyz="0.0" izz="0.00091923080428"/>
    </inertial>
    <visual>
      <origin rpy="3.14159265359 0 0" xyz="0 0 0"/>
      <geometry>
        <mesh filename="file:///home/mam0box/catkin_ws/src/uuv_simulator/uuv_manipulators/oberon7/oberon7_description/meshes/parallel_gripper/visual/Finger.dae"/>
      </geometry>
    </visual>
    <collision>
      <origin rpy="3.14159265359 0 0" xyz="0 0 0"/>
      <geometry>
        <mesh filename="file:///home/mam0box/catkin_ws/src/uuv_simulator/uuv_manipulators/oberon7/oberon7_description/meshes/parallel_gripper/visual/Finger.dae"/>
      </geometry>
    </collision>
  </link>
  <joint name="/finger_right_joint" type="revolute">
    <parent link="/end_effector"/>
    <child link="/finger_right"/>
    <origin rpy="3.14159265359 3.14159265359 3.14159265359" xyz="0.0444267 -0.0391376 0"/>
    <axis xyz="0 0 -1"/>
    <dynamics damping="5" friction="10"/>
    <limit effort="30" lower="0" upper="1.04709283144" velocity="0.15"/>
  </joint>
  <transmission name="/finger_right_joint_trans">
    <type>transmission_interface/SimpleTransmission</type>
    <joint name="/finger_right_joint">
      <hardwareInterface>hardware_interface/EffortJointInterface</hardwareInterface>
    </joint>
    <actuator name="/finger_right_joint_motor">
      <hardwareInterface>hardware_interface/EffortJointInterface</hardwareInterface>
      <mechanicalReduction>1</mechanicalReduction>
    </actuator>
  </transmission>
  <!-- Finger tip right  -->
  <link name="/finger_tip_right">
    <inertial>
      <origin rpy="0 0 0" xyz="0.027744 0.017278 0.0"/>
      <mass value="1.12550524054"/>
      <inertia ixx="0.000611047001819" ixy="0.0" ixz="0.0" iyy="0.00134903081039" iyz="0.0" izz="0.00121555609857"/>
    </inertial>
    <visual>
      <origin rpy="0 0 0" xyz="0 0 0"/>
      <geometry>
        <mesh filename="file:///home/mam0box/catkin_ws/src/uuv_simulator/uuv_manipulators/oberon7/oberon7_description/meshes/parallel_gripper/visual/FingerTip.dae"/>
      </geometry>
    </visual>
    <collision>
      <origin rpy="0 0 0" xyz="0 0 0"/>
      <geometry>
        <mesh filename="file:///home/mam0box/catkin_ws/src/uuv_simulator/uuv_manipulators/oberon7/oberon7_description/meshes/parallel_gripper/visual/FingerTip.dae"/>
      </geometry>
    </collision>
  </link>
  <joint name="/finger_tip_right_joint" type="revolute">
    <parent link="/finger_right"/>
    <child link="/finger_tip_right"/>
    <origin rpy="0 0 0" xyz="0.06431 0 0"/>
    <axis xyz="0 0 1"/>
    <dynamics damping="5" friction="10"/>
    <limit effort="0" lower="0" upper="0" velocity="0"/>
  </joint>
  <gazebo reference="/base">
    <selfCollide>false</selfCollide>
    <maxContacts>1</maxContacts>
  </gazebo>
  <gazebo reference="/shoulder_link">
    <selfCollide>false</selfCollide>
    <maxContacts>1</maxContacts>
  </gazebo>
  <gazebo reference="/upper_link">
    <selfCollide>false</selfCollide>
    <maxContacts>1</maxContacts>
  </gazebo>
  <gazebo reference="/elbow_link">
    <selfCollide>false</selfCollide>
    <maxContacts>1</maxContacts>
  </gazebo>
  <gazebo reference="/forearm">
    <selfCollide>false</selfCollide>
    <maxContacts>1</maxContacts>
  </gazebo>
  <gazebo reference="/wrist_link">
    <selfCollide>false</selfCollide>
    <maxContacts>1</maxContacts>
  </gazebo>
  <gazebo reference="/finger_left">
    <selfCollide>false</selfCollide>
    <kp>1000000.0</kp>
    <kd>1.0</kd>
    <mu1>1.0</mu1>
    <mu2>1.0</mu2>
    <minDepth>0.001</minDepth>
    <maxContacts>1</maxContacts>
    <implicitSpringDamper>1</implicitSpringDamper>
  </gazebo>
  <gazebo reference="/finger_right">
    <selfCollide>false</selfCollide>
    <kp>1000000.0</kp>
    <kd>1.0</kd>
    <mu1>1.0</mu1>
    <mu2>1.0</mu2>
    <minDepth>0.001</minDepth>
    <maxContacts>1</maxContacts>
    <implicitSpringDamper>1</implicitSpringDamper>
  </gazebo>
  <gazebo reference="/finger_tip_left">
    <selfCollide>true</selfCollide>
    <kp>1000000.0</kp>
    <kd>1.0</kd>
    <mu1>1.0</mu1>
    <mu2>1.0</mu2>
    <minDepth>0.001</minDepth>
    <maxContacts>3</maxContacts>
    <implicitSpringDamper>1</implicitSpringDamper>
  </gazebo>
  <gazebo reference="/finger_tip_right">
    <selfCollide>true</selfCollide>
    <kp>1000000.0</kp>
    <kd>1.0</kd>
    <mu1>1.0</mu1>
    <mu2>1.0</mu2>
    <minDepth>0.001</minDepth>
    <maxContacts>3</maxContacts>
    <implicitSpringDamper>1</implicitSpringDamper>
  </gazebo>
  <joint name="/anchor" type="revolute">
    <parent link="world"/>
    <child link="/base"/>
    <origin rpy="0 0 0" xyz="0 0 1.5"/>
    <axis xyz="0 1 0"/>
    <limit effort="0" lower="0" upper="0" velocity="0"/>
  </joint>
</robot>

